<?xml version="1.0"?>
<robot xmlns:xacro="http://www.ros.org/wiki/xacro" name="sar_robot">

  <material name="blue"><color rgba="0 0 0.8 1"/></material>
  <material name="black"><color rgba="0.1 0.1 0.1 1"/></material>

  <link name="base_link">
    <visual>
      <origin xyz="0 0 0.1"/>
      <geometry><box size="0.6 0.4 0.2"/></geometry>
      <material name="blue"/>
    </visual>
    <collision>
      <origin xyz="0 0 0.1"/>
      <geometry><box size="0.6 0.4 0.2"/></geometry>
    </collision>
    <inertial>
      <origin xyz="0 0 0.1"/><mass value="5.0"/>
      <inertia ixx="0.08" ixy="0.0" ixz="0.0" iyy="0.16" iyz="0.0" izz="0.22"/>
    </inertial>
  </link>

  <xacro:macro name="wheel" params="prefix x_reflect y_reflect">
    <link name="${prefix}_wheel">
      <visual>
        <geometry><cylinder radius="0.1" length="0.04"/></geometry>
        <material name="black"/>
      </visual>
      <collision>
        <geometry><cylinder radius="0.1" length="0.04"/></geometry>
      </collision>
      <inertial>
        <mass value="0.5"/>
        <inertia ixx="0.001" ixy="0.0" ixz="0.0" iyy="0.001" iyz="0.0" izz="0.002"/>
      </inertial>
    </link>
    <joint name="${prefix}_wheel_joint" type="continuous">
      <parent link="base_link"/>
      <child link="${prefix}_wheel"/>
      <origin xyz="${x_reflect*0.2} ${y_reflect*0.22} 0.1" rpy="${-pi/2} 0 0"/>
      <axis xyz="0 0 1"/>
    </joint>
  </xacro:macro>

  <xacro:wheel prefix="front_left"  x_reflect="1"  y_reflect="1" />
  <xacro:wheel prefix="front_right" x_reflect="1"  y_reflect="-1" />
  <xacro:wheel prefix="back_left"   x_reflect="-1" y_reflect="1" />
  <xacro:wheel prefix="back_right"  x_reflect="-1" y_reflect="-1" />

  <gazebo>
    <plugin filename="gz-sim-sensors-system" name="gz::sim::systems::Sensors">
      <render_engine>ogre</render_engine>
    </plugin>

    <plugin filename="gz-sim-diff-drive-system" name="gz::sim::systems::DiffDrive">
      <left_joint>front_left_wheel_joint</left_joint>
      <right_joint>front_right_wheel_joint</right_joint>
      <wheel_separation>0.44</wheel_separation>
      <wheel_radius>0.1</wheel_radius>
      <topic>cmd_vel</topic>
      <odom_topic>odom</odom_topic>
      <frame_id>odom</frame_id>
      <child_frame_id>base_link</child_frame_id>
    </plugin>
  </gazebo>

  <link name="laser_frame">
    <visual><geometry><cylinder radius="0.05" length="0.04"/></geometry><material name="black"/></visual>
    <collision><geometry><cylinder radius="0.05" length="0.04"/></geometry></collision>
    <inertial><mass value="0.1"/><inertia ixx="0.0001" ixy="0" ixz="0" iyy="0.0001" iyz="0" izz="0.0002"/></inertial>
  </link>
  <joint name="laser_joint" type="fixed">
    <parent link="base_link"/><child link="laser_frame"/><origin xyz="0.1 0 0.22" rpy="0 0 0"/>
  </joint>

  <gazebo reference="laser_frame">
    <sensor name="lidar" type="gpu_lidar">
      <always_on>true</always_on><update_rate>10</update_rate><visualize>true</visualize><topic>/scan</topic>
      <gz_frame_id>laser_frame</gz_frame_id>
      <lidar><scan><horizontal><samples>360</samples><min_angle>-3.14</min_angle><max_angle>3.14</max_angle></horizontal></scan>
      <range><min>0.12</min><max>12.0</max></range></lidar>
    </sensor>
  </gazebo>
</robot>