<?xml version="1.0"?>
<robot xmlns:xacro="http://www.ros.org/wiki/xacro" name="sar_robot">

  <material name="blue"><color rgba="0 0 0.8 1"/></material>
  <material name="black"><color rgba="0.1 0.1 0.1 1"/></material>

  <link name="base_link">
    <visual>
      <origin xyz="0 0 0.1"/>
      <geometry><box size="0.6 0.4 0.2"/></geometry>
      <material name="blue"/>
    </visual>
    <collision>
      <origin xyz="0 0 0.1"/>
      <geometry><box size="0.6 0.4 0.2"/></geometry>
    </collision>
    <inertial>
      <origin xyz="0 0 0.1"/><mass value="5.0"/>
      <inertia ixx="0.08" ixy="0.0" ixz="0.0" iyy="0.16" iyz="0.0" izz="0.22"/>
    </inertial>
  </link>

  <xacro:macro name="wheel" params="prefix x_reflect y_reflect">
    <link name="${prefix}_wheel">
      <visual>
        <geometry><cylinder radius="0.1" length="0.04"/></geometry>
        <material name="black"/>
      </visual>
      <collision>
        <geometry><cylinder radius="0.1" length="0.04"/></geometry>
      </collision>
      <inertial>
        <mass value="0.5"/>
        <inertia ixx="0.001" ixy="0.0" ixz="0.0" iyy="0.001" iyz="0.0" izz="0.002"/>
      </inertial>
    </link>

    <joint name="${prefix}_wheel_joint" type="continuous">
      <parent link="base_link"/>
      <child link="${prefix}_wheel"/>
      <origin xyz="${x_reflect*0.2} ${y_reflect*0.22} 0.05" rpy="${y_reflect*pi/2} 0 0"/>
      <axis xyz="0 0 1"/>
    </joint>
  </xacro:macro>

  <xacro:wheel prefix="front_left"  x_reflect="1"  y_reflect="1" />
  <xacro:wheel prefix="front_right" x_reflect="1"  y_reflect="-1" />
  <xacro:wheel prefix="back_left"   x_reflect="-1" y_reflect="1" />
  <xacro:wheel prefix="back_right"  x_reflect="-1" y_reflect="-1" />

  <gazebo>
    <plugin filename="gz-sim-diff-drive-system" name="gz::sim::systems::DiffDrive">
      <left_joint>front_left_wheel_joint</left_joint>
      <left_joint>back_left_wheel_joint</left_joint>
      <right_joint>front_right_wheel_joint</right_joint>
      <right_joint>back_right_wheel_joint</right_joint>
      
      <wheel_separation>0.44</wheel_separation>
      <wheel_radius>0.1</wheel_radius>
      <topic>cmd_vel</topic>
    </plugin>
  </gazebo>
</robot>